Workbook

Sheet Dashboard
A2: SWE Plan dashboard
A4: Plan start | B4: 46294 | E4: Plan length | F4: 24 weeks | J4: Update tasks in Master Plan. All views recalculate in Excel.
A6: TOTAL TASKS | E6: CORE COMPLETE | J6: BLOCKED | N6: ACTUAL HOURS
A7: =COUNTA(PlanTasks[Task ID]) -> 236 | E7: =IF(COUNTIFS(PlanTasks[Scope],"Core")=0,"",COUNTIFS(PlanTasks[Scope],"Core",PlanTasks[Completion check],"Complete")/COUNTIFS(PlanTasks[Scope],"Core")) -> 0.0088495575 | J7: =COUNTIFS(PlanTasks[Status],"Blocked") -> 0 | N7: =SUM(PlanTasks[Actual (h)]) -> 0.5
A11: Category | B11: Tasks | C11: Complete | D11: Progress | E11: Active | F11: Blocked | G11: Est. (h) | H11: Actual (h)
A12: Engineering | B12: =COUNTIFS(PlanTasks[Category],$A12) -> 15 | C12: =COUNTIFS(PlanTasks[Category],$A12,PlanTasks[Completion check],"Complete") -> 1 | D12: =IF(B12=0,"",C12/B12) -> 0.066666667 | E12: =COUNTIFS(PlanTasks[Category],$A12,PlanTasks[Status],"In progress") -> 0 | F12: =COUNTIFS(PlanTasks[Category],$A12,PlanTasks[Status],"Blocked") -> 0 | G12: =SUMIFS(PlanTasks[Estimate (h)],PlanTasks[Category],$A12) -> 15.75 | H12: =SUMIFS(PlanTasks[Actual (h)],PlanTasks[Category],$A12) -> 0.25
A13: Java & Spring | B13: =COUNTIFS(PlanTasks[Category],$A13) -> 31 | C13: =COUNTIFS(PlanTasks[Category],$A13,PlanTasks[Completion check],"Complete") -> 0 | D13: =IF(B13=0,"",C13/B13) -> 0 | E13: =COUNTIFS(PlanTasks[Category],$A13,PlanTasks[Status],"In progress") -> 0 | F13: =COUNTIFS(PlanTasks[Category],$A13,PlanTasks[Status],"Blocked") -> 0 | G13: =SUMIFS(PlanTasks[Estimate (h)],PlanTasks[Category],$A13) -> 23.25 | H13: =SUMIFS(PlanTasks[Actual (h)],PlanTasks[Category],$A13) -> 0
A14: TypeScript & UI | B14: =COUNTIFS(PlanTasks[Category],$A14) -> 29 | C14: =COUNTIFS(PlanTasks[Category],$A14,PlanTasks[Completion check],"Complete") -> 0 | D14: =IF(B14=0,"",C14/B14) -> 0 | E14: =COUNTIFS(PlanTasks[Category],$A14,PlanTasks[Status],"In progress") -> 0 | F14: =COUNTIFS(PlanTasks[Category],$A14,PlanTasks[Status],"Blocked") -> 0 | G14: =SUMIFS(PlanTasks[Estimate (h)],PlanTasks[Category],$A14) -> 21.75 | H14: =SUMIFS(PlanTasks[Actual (h)],PlanTasks[Category],$A14) -> 0
A15: CS & SQL | B15: =COUNTIFS(PlanTasks[Category],$A15) -> 15 | C15: =COUNTIFS(PlanTasks[Category],$A15,PlanTasks[Completion check],"Complete") -> 0 | D15: =IF(B15=0,"",C15/B15) -> 0 | E15: =COUNTIFS(PlanTasks[Category],$A15,PlanTasks[Status],"In progress") -> 0 | F15: =COUNTIFS(PlanTasks[Category],$A15,PlanTasks[Status],"Blocked") -> 0 | G15: =SUMIFS(PlanTasks[Estimate (h)],PlanTasks[Category],$A15) -> 11.5 | H15: =SUMIFS(PlanTasks[Actual (h)],PlanTasks[Category],$A15) -> 0
A16: DSA | B16: =COUNTIFS(PlanTasks[Category],$A16) -> 24 | C16: =COUNTIFS(PlanTasks[Category],$A16,PlanTasks[Completion check],"Complete") -> 0 | D16: =IF(B16=0,"",C16/B16) -> 0 | E16: =COUNTIFS(PlanTasks[Category],$A16,PlanTasks[Status],"In progress") -> 0 | F16: =COUNTIFS(PlanTasks[Category],$A16,PlanTasks[Status],"Blocked") -> 0 | G16: =SUMIFS(PlanTasks[Estimate (h)],PlanTasks[Category],$A16) -> 72 | H16: =SUMIFS(PlanTasks[Actual (h)],PlanTasks[Category],$A16) -> 0
A17: System design | B17: =COUNTIFS(PlanTasks[Category],$A17) -> 10 | C17: =COUNTIFS(PlanTasks[Category],$A17,PlanTasks[Completion check],"Complete") -> 0 | D17: =IF(B17=0,"",C17/B17) -> 0 | E17: =COUNTIFS(PlanTasks[Category],$A17,PlanTasks[Status],"In progress") -> 0 | F17: =COUNTIFS(PlanTasks[Category],$A17,PlanTasks[Status],"Blocked") -> 0 | G17: =SUMIFS(PlanTasks[Estimate (h)],PlanTasks[Category],$A17) -> 10 | H17: =SUMIFS(PlanTasks[Actual (h)],PlanTasks[Category],$A17) -> 0
A18: Projects | B18: =COUNTIFS(PlanTasks[Category],$A18) -> 30 | C18: =COUNTIFS(PlanTasks[Category],$A18,PlanTasks[Completion check],"Complete") -> 0 | D18: =IF(B18=0,"",C18/B18) -> 0 | E18: =COUNTIFS(PlanTasks[Category],$A18,PlanTasks[Status],"In progress") -> 0 | F18: =COUNTIFS(PlanTasks[Category],$A18,PlanTasks[Status],"Blocked") -> 0 | G18: =SUMIFS(PlanTasks[Estimate (h)],PlanTasks[Category],$A18) -> 52.5 | H18: =SUMIFS(PlanTasks[Actual (h)],PlanTasks[Category],$A18) -> 0
A19: AI Engineering | B19: =COUNTIFS(PlanTasks[Category],$A19) -> 7 | C19: =COUNTIFS(PlanTasks[Category],$A19,PlanTasks[Completion check],"Complete") -> 0 | D19: =IF(B19=0,"",C19/B19) -> 0 | E19: =COUNTIFS(PlanTasks[Category],$A19,PlanTasks[Status],"In progress") -> 1 | F19: =COUNTIFS(PlanTasks[Category],$A19,PlanTasks[Status],"Blocked") -> 0 | G19: =SUMIFS(PlanTasks[Estimate (h)],PlanTasks[Category],$A19) -> 5.25 | H19: =SUMIFS(PlanTasks[Actual (h)],PlanTasks[Category],$A19) -> 0
A20: Mock interviews | B20: =COUNTIFS(PlanTasks[Category],$A20) -> 44 | C20: =COUNTIFS(PlanTasks[Category],$A20,PlanTasks[Completion check],"Complete") -> 0 | D20: =IF(B20=0,"",C20/B20) -> 0 | E20: =COUNTIFS(PlanTasks[Category],$A20,PlanTasks[Status],"In progress") -> 0 | F20: =COUNTIFS(PlanTasks[Category],$A20,PlanTasks[Status],"Blocked") -> 0 | G20: =SUMIFS(PlanTasks[Estimate (h)],PlanTasks[Category],$A20) -> 44 | H20: =SUMIFS(PlanTasks[Actual (h)],PlanTasks[Category],$A20) -> 0
A21: Review | B21: =COUNTIFS(PlanTasks[Category],$A21) -> 25 | C21: =COUNTIFS(PlanTasks[Category],$A21,PlanTasks[Completion check],"Complete") -> 1 | D21: =IF(B21=0,"",C21/B21) -> 0.04 | E21: =COUNTIFS(PlanTasks[Category],$A21,PlanTasks[Status],"In progress") -> 0 | F21: =COUNTIFS(PlanTasks[Category],$A21,PlanTasks[Status],"Blocked") -> 0 | G21: =SUMIFS(PlanTasks[Estimate (h)],PlanTasks[Category],$A21) -> 13 | H21: =SUMIFS(PlanTasks[Actual (h)],PlanTasks[Category],$A21) -> 0.25
A22: Career | B22: =COUNTIFS(PlanTasks[Category],$A22) -> 6 | C22: =COUNTIFS(PlanTasks[Category],$A22,PlanTasks[Completion check],"Complete") -> 0 | D22: =IF(B22=0,"",C22/B22) -> 0 | E22: =COUNTIFS(PlanTasks[Category],$A22,PlanTasks[Status],"In progress") -> 0 | F22: =COUNTIFS(PlanTasks[Category],$A22,PlanTasks[Status],"Blocked") -> 0 | G22: =SUMIFS(PlanTasks[Estimate (h)],PlanTasks[Category],$A22) -> 5 | H22: =SUMIFS(PlanTasks[Actual (h)],PlanTasks[Category],$A22) -> 0
A24: Category coverage | B24: =A7-SUM(B12:B22) -> 0 | C24: Tasks outside the listed categories
J25: Complete = evidence + completion date; mocks also require scores and a result.
A26: Category totals include optional work. Effort estimates are proposed; record actual hours as you work.
A29: Week | B29: Core (h) | C29: Capacity (h) | D29: Actual (h) | E29: Complete | F29: Core tasks | G29: Progress | H29: Spare (h)
A30: ='Weekly Review'!A10 -> 1 | B30: ='Weekly Review'!E10 -> 16.25 | C30: ='Weekly Review'!D10 -> 13 | D30: ='Weekly Review'!G10 -> 0.5 | E30: ='Weekly Review'!I10 -> 2 | F30: ='Weekly Review'!H10 -> 15 | G30: ='Weekly Review'!J10 -> 0.13333333 | H30: ='Weekly Review'!K10 -> -3.25
A31: ='Weekly Review'!A11 -> 2 | B31: ='Weekly Review'!E11 -> 11 | C31: ='Weekly Review'!D11 -> 13 | D31: ='Weekly Review'!G11 -> 0 | E31: ='Weekly Review'!I11 -> 0 | F31: ='Weekly Review'!H11 -> 10 | G31: ='Weekly Review'!J11 -> 0 | H31: ='Weekly Review'!K11 -> 2
A32: ='Weekly Review'!A12 -> 3 | B32: ='Weekly Review'!E12 -> 11.75 | C32: ='Weekly Review'!D12 -> 13 | D32: ='Weekly Review'!G12 -> 0 | E32: ='Weekly Review'!I12 -> 0 | F32: ='Weekly Review'!H12 -> 11 | G32: ='Weekly Review'!J12 -> 0 | H32: ='Weekly Review'!K12 -> 1.25
A33: ='Weekly Review'!A13 -> 4 | B33: ='Weekly Review'!E13 -> 13.5 | C33: ='Weekly Review'!D13 -> 13 | D33: ='Weekly Review'!G13 -> 0 | E33: ='Weekly Review'!I13 -> 0 | F33: ='Weekly Review'!H13 -> 13 | G33: ='Weekly Review'!J13 -> 0 | H33: ='Weekly Review'!K13 -> -0.5
A34: ='Weekly Review'!A14 -> 5 | B34: ='Weekly Review'!E14 -> 15.5 | C34: ='Weekly Review'!D14 -> 14 | D34: ='Weekly Review'!G14 -> 0 | E34: ='Weekly Review'!I14 -> 0 | F34: ='Weekly Review'!H14 -> 15 | G34: ='Weekly Review'!J14 -> 0 | H34: ='Weekly Review'!K14 -> -1.5
A35: ='Weekly Review'!A15 -> 6 | B35: ='Weekly Review'!E15 -> 11 | C35: ='Weekly Review'!D15 -> 14 | D35: ='Weekly Review'!G15 -> 0 | E35: ='Weekly Review'!I15 -> 0 | F35: ='Weekly Review'!H15 -> 10 | G35: ='Weekly Review'!J15 -> 0 | H35: ='Weekly Review'!K15 -> 3
A36: ='Weekly Review'!A16 -> 7 | B36: ='Weekly Review'!E16 -> 11.25 | C36: ='Weekly Review'!D16 -> 14 | D36: ='Weekly Review'!G16 -> 0 | E36: ='Weekly Review'!I16 -> 0 | F36: ='Weekly Review'!H16 -> 10 | G36: ='Weekly Review'!J16 -> 0 | H36: ='Weekly Review'!K16 -> 2.75
A37: ='Weekly Review'!A17 -> 8 | B37: ='Weekly Review'!E17 -> 10.25 | C37: ='Weekly Review'!D17 -> 14 | D37: ='Weekly Review'!G17 -> 0 | E37: ='Weekly Review'!I17 -> 0 | F37: ='Weekly Review'!H17 -> 8 | G37: ='Weekly Review'!J17 -> 0 | H37: ='Weekly Review'!K17 -> 3.75
A38: ='Weekly Review'!A18 -> 9 | B38: ='Weekly Review'!E18 -> 10.75 | C38: ='Weekly Review'!D18 -> 15 | D38: ='Weekly Review'!G18 -> 0 | E38: ='Weekly Review'!I18 -> 0 | F38: ='Weekly Review'!H18 -> 9 | G38: ='Weekly Review'!J18 -> 0 | H38: ='Weekly Review'!K18 -> 4.25
A39: ='Weekly Review'!A19 -> 10 | B39: ='Weekly Review'!E19 -> 11.25 | C39: ='Weekly Review'!D19 -> 15 | D39: ='Weekly Review'!G19 -> 0 | E39: ='Weekly Review'!I19 -> 0 | F39: ='Weekly Review'!H19 -> 10 | G39: ='Weekly Review'!J19 -> 0 | H39: ='Weekly Review'!K19 -> 3.75
A40: ='Weekly Review'!A20 -> 11 | B40: ='Weekly Review'!E20 -> 11.25 | C40: ='Weekly Review'!D20 -> 15 | D40: ='Weekly Review'!G20 -> 0 | E40: ='Weekly Review'!I20 -> 0 | F40: ='Weekly Review'!H20 -> 10 | G40: ='Weekly Review'!J20 -> 0 | H40: ='Weekly Review'!K20 -> 3.75
A41: ='Weekly Review'!A21 -> 12 | B41: ='Weekly Review'!E21 -> 10.75 | C41: ='Weekly Review'!D21 -> 15 | D41: ='Weekly Review'!G21 -> 0 | E41: ='Weekly Review'!I21 -> 0 | F41: ='Weekly Review'!H21 -> 9 | G41: ='Weekly Review'!J21 -> 0 | H41: ='Weekly Review'!K21 -> 4.25
... A49: ='Weekly Review'!A29 -> 20 | B49: ='Weekly Review'!E29 -> 12 | C49: ='Weekly Review'!D29 -> 15 | D49: ='Weekly Review'!G29 -> 0 | E49: ='Weekly Review'!I29 -> 0 | F49: ='Weekly Review'!H29 -> 11 | G49: ='Weekly Review'!J29 -> 0 | H49: ='Weekly Review'!K29 -> 3
A50: ='Weekly Review'!A30 -> 21 | B50: ='Weekly Review'!E30 -> 9.25 | C50: ='Weekly Review'!D30 -> 15 | D50: ='Weekly Review'!G30 -> 0 | E50: ='Weekly Review'!I30 -> 0 | F50: ='Weekly Review'!H30 -> 7 | G50: ='Weekly Review'!J30 -> 0 | H50: ='Weekly Review'!K30 -> 5.75 | J50: DSA solved | L50: ='Weekly Review'!F4 -> 0 | N50: Target | P50: ='Weekly Review'!I4 -> 145
A51: ='Weekly Review'!A31 -> 22 | B51: ='Weekly Review'!E31 -> 8.5 | C51: ='Weekly Review'!D31 -> 15 | D51: ='Weekly Review'!G31 -> 0 | E51: ='Weekly Review'!I31 -> 0 | F51: ='Weekly Review'!H31 -> 6 | G51: ='Weekly Review'!J31 -> 0 | H51: ='Weekly Review'!K31 -> 6.5
A52: ='Weekly Review'!A32 -> 23 | B52: ='Weekly Review'!E32 -> 8.5 | C52: ='Weekly Review'!D32 -> 15 | D52: ='Weekly Review'!G32 -> 0 | E52: ='Weekly Review'!I32 -> 0 | F52: ='Weekly Review'!H32 -> 6 | G52: ='Weekly Review'!J32 -> 0 | H52: ='Weekly Review'!K32 -> 6.5 | J52: Mocks passed | L52: ='Weekly Review'!F5 -> 0 | N52: Attempted | P52: ='Weekly Review'!I5 -> 0
A53: ='Weekly Review'!A33 -> 24 | B53: ='Weekly Review'!E33 -> 8.5 | C53: ='Weekly Review'!D33 -> 15 | D53: ='Weekly Review'!G33 -> 0 | E53: ='Weekly Review'!I33 -> 0 | F53: ='Weekly Review'!H33 -> 6 | G53: ='Weekly Review'!J33 -> 0 | H53: ='Weekly Review'!K33 -> 6.5
A55: A negative spare-hours value means core work exceeds the weekly capacity. | J55: Review workload before adding optional tasks.
A58: Progress by plan section
A60: Plan section | B60: Tasks | C60: Complete | D60: Progress | E60: Active | F60: Blocked | G60: Est. (h) | H60: Actual (h) | J60: Section coverage | L60: =A7-SUM(B61:B160) -> 0
...

Sheet Master Plan
A1: Software engineering interview plan
A2: Edit tasks here. Dashboard and category tabs update from this table in the same order.
A3: Amber cells are inputs. Add tasks inside PlanTasks. Category key is calculated. Set the plan start date in Weekly Review.
A5: Task ID | B5: Start week | C5: Category | D5: Work type | E5: Task / deliverable | F5: Priority | G5: Status | H5: Evidence / result | I5: Next action / blocker | J5: Due date | K5: Scope | L5: Estimate (h) | M5: Actual (h) | N5: Confidence 0-5 | O5: Done when | P5: Exercise / interview prompt | Q5: Prerequisite IDs | R5: Completed on | S5: Review due | T5: AI practice mode | U5: Origin | V5: Original source rows | W5: Source IDs | X5: End week | Y5: Plan section | Z5: Technical 0-5 | AA5: Communication 0-5 | AB5: Mock result | AC5: Original schedule / reviews | AD5: Completion check | AE5: Category key
A6: G01 | B6: 1 | C6: Review | D6: Setup | E6: Set the target role, baseline and weekly time budget | F6: P0 | G6: Done | H6: java --version, javac --version, npm --version, nvm --version | J6: =IF('Weekly Review'!$C$4="","",'Weekly Review'!$C$4+(X6-1)*7+6) -> 46300 | K6: Core | L6: 1 | M6: 0.25 | N6: 5 | O6: Record target roles, start date, available weekly hours and current Java/TS/SQL baseline. Review the proposed task estimates and optional scope. | R6: 46294 | S6: =IF(R6="","",R6+'Weekly Review'!$C$5) -> 46301 | T6: AI-free first | U6: New gap task | X6: 1 | Y6: Gap closure | Z6: 5 | AA6: 5 | AB6: Strong Pass | AD6: =IF(G6="Done",IF(H6="","Add evidence",IF(R6="","Add completion date",IF(D6="Mock",IF(OR(Z6="",AA6="",AB6="",AB6="Not Attempted"),"Record mock results","Complete"),"Complete"))),"") -> Complete | AE6: =C6&"|"&COUNTIFS($C$6:C6,C6) -> Review|1
A7: G02 | B7: 1 | C7: Engineering | D7: Setup | E7: Run both toolchains and a first test from a clean clone | F7: P0 | G7: Done | H7: already workedon java & js/ts projects | J7: =IF('Weekly Review'!$C$4="","",'Weekly Review'!$C$4+(X7-1)*7+6) -> 46300 | K7: Core | L7: 1.5 | M7: 0.25 | N7: 5 | O7: Install compatible JDK/Node tools, pin project versions and lockfiles, run Java tests and TypeScript typecheck/tests, and commit setup instructions. | R7: 46294 | S7: =IF(R7="","",R7+'Weekly Review'!$C$5) -> 46301 | T7: AI-free first | U7: New gap task | X7: 1 | Y7: Gap closure | Z7: 5 | AA7: 5 | AB7: Strong Pass | AD7: =IF(G7="Done",IF(H7="","Add evidence",IF(R7="","Add completion date",IF(D7="Mock",IF(OR(Z7="",AA7="",AB7="",AB7="Not Attempted"),"Record mock results","Complete"),"Complete"))),"") -> Complete | AE7: =C7&"|"&COUNTIFS($C$6:C7,C7) -> Engineering|1
A8: AI18 | B8: 1 | C8: AI Engineering | D8: Learn | E8: Confirm round policy and rehearse AI-free fallback | F8: P0 | G8: In progress | J8: =IF('Weekly Review'!$C$4="","",'Weekly Review'!$C$4+(X8-1)*7+6) -> 46300 | K8: Core | L8: 0.75 | M8: 0 | N8: 0 | O8: Confirm exact permitted tools and boundaries Code/debug/explain with no assistant Implement and explain independently Solve/debug/explain without AI when required | P8: Transparent AI-assisted session Failure to test: Policy violation 60-min unaided mock Failure to test: Dependency on tools Redo representative task without any assistant Practice mode: AI-free Yes, AI-assisted No | S8: =IF(R8="","",R8+'Weekly Review'!$C$5) | T8: AI-free first | U8: Merged | V8: AI Engineering!18 AI Engineering!19 Real-World Eng!19 Master Roadmap!75 | W8: S026 S027 S025 | X8: 1 | Y8: Interview Policy | AC8: W22–24 Review: Repeat until interview W21–24 | AD8: =IF(G8="Done",IF(H8="","Add evidence",IF(R8="","Add completion date",IF(D8="Mock",IF(OR(Z8="",AA8="",AB8="",AB8="Not Attempted"),"Record mock results","Complete"),"Complete"))),"") | AE8: =C8&"|"&COUNTIFS($C$6:C8,C8) -> AI Engineering|1
A9: CS12 | B9: 1 | C9: CS & SQL | D9: Learn | E9: JOINs | F9: P0 | G9: Not started | J9: =IF('Weekly Review'!$C$4="","",'Weekly Review'!$C$4+(X9-1)*7+6) -> 46300 | K9: Core | L9: 0.75 | M9: 0 | N9: 0 | O9: INNER/LEFT and multi-table reasoning JOINs, GROUP BY, HAVING, subqueries, CTEs, CASE, aggregates | P9: Interview: Return customers with/without orders | S9: =IF(R9="","",R9+'Weekly Review'!$C$5) | T9: AI-free first | U9: Merged | V9: CS Fundamentals!12 Master Roadmap!25 | W9: S020 | X9: 1 | Y9: SQL | AC9: W1–2 Review: W4 + W21–24 W1 | AD9: =IF(G9="Done",IF(H9="","Add evidence",IF(R9="","Add completion date",IF(D9="Mock",IF(OR(Z9="",AA9="",AB9="",AB9="Not Attempted"),"Record mock results","Complete"),"Complete"))),"") | AE9: =C9&"|"&COUNTIFS($C$6:C9,C9) -> CS & SQL|1
A10: JA05 | B10: 1 | C10: Java & Spring | D10: Learn | E10: Syntax + object model | F10: P0 | G10: Not started | J10: =IF('Weekly Review'!$C$4="","",'Weekly Review'!$C$4+(X10-1)*7+6) -> 46300 | K10: Core | L10: 0.75 | M10: 0 | N10: 0 | O10: types, references, methods, packages, access modifiers OOP, collections, generics, exceptions, streams, records, sealed classes Write clean Java; primitives/references, methods, packages, exceptions | P10: 20 small Java drills Interview: primitive vs reference? pass-by-value? Implement a domain service and explain object/model choices Build Java kata + service layer Primary backend language Complete 20 Java coding drills | S10: =IF(R10="","",R10+'Weekly Review'!$C$5) | T10: AI-free first | U10: Merged | V10: Java + Spring Boot!5 Full-Stack Stack!5 Master Roadmap!80 | W10: S001 | X10: 1 | Y10: Java Core | AC10: W1 Review: W4 + W21–24 | AD10: =IF(G10="Done",IF(H10="","Add evidence",IF(R10="","Add completion date",IF(D10="Mock",IF(OR(Z10="",AA10="",AB10="",AB10="Not Attempted"),"Record mock results","Complete"),"Complete"))),"") | AE10: =C10&"|"&COUNTIFS($C$6:C10,C10) -> Java & Spring|1
A11: JA06 | B11: 1 | C11: Java & Spring | D11: Learn | E11: OOP | F11: P0 | G11: Not started | J11: =IF('Weekly Review'!$C$4="","",'Weekly Review'!$C$4+(X11-1)*7+6) -> 46307 | K11: Core | L11: 0.75 | M11: 0 | N11: 0 | O11: encapsulation, abstraction, inheritance, polymorphism, composition Explain each and when composition is preferable Apply principles without overengineering Encapsulation, composition, interfaces, SOLID trade-offs Model domains with classes/interfaces; composition, immutability, dependency boundaries | P11: model order/payment domain Interview: composition vs inheritance? Interview: Composition vs inheritance? Interview: Which SOLID principle is violated here? Refactor a service using composition | Q11: G02 | S11: =IF(R11="","",R11+'Weekly Review'!$C$5) | T11: AI-free first | U11: Merged | V11: Java + Spring Boot!6 CS Fundamentals!5 CS Fundamentals!6 Master Roadmap!21 Master Roadmap!81 | W11: S001 S019 | X11: 2 | Y11: Java Core | AC11: W1 Review: W4 + W21–24 W2 | AD11: =IF(G11="Done",IF(H11="","Add evidence",IF(R11="","Add completion date",IF(D11="Mock",IF(OR(Z11="",AA11="",AB11="",AB11="Not Attempted"),"Record mock results","Complete"),"Complete"))),"") | AE11: =C11&"|"&COUNTIFS($C$6:C11,C11) -> Java & Spring|2
A12: TS05 | B12: 1 | C12: TypeScript & UI | D12: Learn | E12: Scopes / closures | F12: P0 | G12: Not started | J12: =IF('Weekly Review'!$C$4="","",'Weekly Review'!$C$4+(X12-1)*7+6) -> 46300 | K12: Core | L12: 0.75 | M12: 0 | N12: 0 | O12: lexical scope, closure use and pitfalls | P12: closure/event handler drills Interview: explain a closure bug | S12: =IF(R12="","",R12+'Weekly Review'!$C$5) | T12: AI-free first | U12: Existing | V12: TypeScript Track!5 | W12: S014 | X12: 1 | Y12: JavaScript Core | AC12: W1 Review: W4 + W21–24 | AD12: =IF(G12="Done",IF(H12="","Add evidence",IF(R12="","Add completion date",IF(D12="Mock",IF(OR(Z12="",AA12="",AB12="",AB12="Not Attempted"),"Record mock results","Complete"),"Complete"))),"") | AE12: =C12&"|"&COUNTIFS($C$6:C12,C12) -> TypeScript & UI|1
A13: TS08 | B13: 1 | C13: TypeScript & UI | D13: Learn | E13: Strict types | F13: P0 | G13: Not started | J13: =IF('Weekly Review'!$C$4="","",'Weekly Review'!$C$4+(X13-1)*7+6) -> 46300 | K13: Core | L13: 0.75 | M13: 0 | N13: 0 | O13: strict mode, inference, annotations, nullability strict typing, generics, narrowing, unions, utility types, async, ESM Types, closures, event loop, promises, async/await, modules, errors strict mode, unions/intersections, generics, narrowing, utility types | P13: convert JS module to strict TS Interview: why avoid any? unknown vs any? Refactor unsafe JS into strict TypeScript Strict TS utility/API module Primary frontend/full-stack language Enable strict mode and remove unsafe any | S13: =IF(R13="","",R13+'Weekly Review'!$C$5) | T13: AI-free first | U13: Merged | V13: TypeScript Track!8 Full-Stack Stack!6 Master Roadmap!19 Master Roadmap!99 | W13: S015 S017 | X13: 1 | Y13: TypeScript Core | AC13: W1 Review: W4 + W21–24 | AD13: =IF(G13="Done",IF(H13="","Add evidence",IF(R13="","Add completion date",IF(D13="Mock",IF(OR(Z13="",AA13="",AB13="",AB13="Not Attempted"),"Record mock results","Complete"),"Complete"))),"") | AE13: =C13&"|"&COUNTIFS($C$6:C13,C13) -> TypeScript & UI|2
A14: TS26 | B14: 1 | C14: TypeScript & UI | D14: Learn | E14: pnpm/npm + lockfiles | F14: P1 | G14: Not started | J14: =IF('Weekly Review'!$C$4="","",'Weekly Review'!$C$4+(X14-1)*7+6) -> 46300 | K14: Core | L14: 0.75 | M14: 0 | N14: 0 | O14: scripts, dependency graph, lockfile reproducibility package.json, lockfiles, scripts, dependency hygiene | P14: clean build from fresh clone Interview: why commit lockfile? Explain reproducible frontend builds Clean TS build pipeline TypeScript tooling | S14: =IF(R14="","",R14+'Weekly Review'!$C$5) | T14: AI-free first | U14: Merged | V14: TypeScript Track!26 Full-Stack Stack!25 | W14: S015 | X14: 1 | Y14: Tooling | AC14: W1 Review: W4 + W21–24 | AD14: =IF(G14="Done",IF(H14="","Add evidence",IF(R14="","Add completion date",IF(D14="Mock",IF(OR(Z14="",AA14="",AB14="",AB14="Not Attempted"),"Record mock results","Complete"),"Complete"))),"") | AE14: =C14&"|"&COUNTIFS($C$6:C14,C14) -> TypeScript & UI|3
A15: EN26 | B15: 1 | C15: Engineering | D15: Build | E15: Git | F15: P1 | G15: Not started | J15: =IF('Weekly Review'!$C$4="","",'Weekly Review'!$C$4+(X15-1)*7+6) -> 46300 | K15: Core | L15: 1 | M15: 0 | N15: 0 | O15: branch, commit, merge/rebase, conflict, PR, bisect concept Branching, merge/rebase, conflicts, PR workflow | P15: Resolve a conflict and explain history PR-based practice Shared | S15: =IF(R15="","",R15+'Weekly Review'!$C$5) | T15: AI-free first | U15: Merged | V15: Full-Stack Stack!26 Master Roadmap!61 | W15: S024 | X15: 1 | Y15: Tooling | AC15: W1 + throughout Review: W4 + W21–24 | AD15: =IF(G15="Done",IF(H15="","Add evidence",IF(R15="","Add completion date",IF(D15="Mock",IF(OR(Z15="",AA15="",AB15="",AB15="Not Attempted"),"Record mock results","Complete"),"Complete"))),"") | AE15: =C15&"|"&COUNTIFS($C$6:C15,C15) -> Engineering|2
A16: B01 | B16: 1 | C16: Projects | D16: Build | E16: Set up Java/TS repo; Java domain kata; convert a small JS module to strict TS | F16: P1 | G16: Not started | J16: =IF('Weekly Review'!$C$4="","",'Weekly Review'!$C$4+(X16-1)*7+6) -> 46300 | K16: Core | L16: 2 | M16: 0 | N16: 0 | O16: Demonstrate the working output, relevant tests, and one design trade-off. | P16: CS/SQL: OOP pillars + basic SELECT/WHERE/JOIN Design: Requirements + simple API/data model AI practice: AI-free baseline; explain every line yourself Set up Java/TS repo; Java domain kata; convert a small JS module to strict TS Sketch a simple booking/order API and 3–4 core entities No-AI baseline: solve/explain without assistant | Q16: G02 | S16: =IF(R16="","",R16+'Weekly Review'!$C$5) | T16: AI-free first | U16: Merged | V16: 24-Week Plan!5 Weekly Task Navigator!5 | X16: 1 | Y16: Dual Foundations | AD16: =IF(G16="Done",IF(H16="","Add evidence",IF(R16="","Add completion date",IF(D16="Mock",IF(OR(Z16="",AA16="",AB16="",AB16="Not Attempted"),"Record mock results","Complete"),"Complete"))),"") | AE16: =C16&"|"&COUNTIFS($C$6:C16,C16) -> Projects|1
A17: DS01 | B17: 1 | C17: DSA | D17: Practice | E17: Solve 7 new DSA problems and revisit errors | F17: P0 | G17: Not started | J17: =IF('Weekly Review'!$C$4="","",'Weekly Review'!$C$4+(X17-1)*7+6) -> 46300 | K17: Core | L17: 3 | M17: 0 | N17: 0 | O17: Record 7 distinct new problem IDs, explain complexity, and retry one earlier mistake without hints. | P17: Complexity & arrays (bank target 8) Use Practice Bank for topic totals. Do not count repeat solutions as new problems. | S17: =IF(R17="","",R17+'Weekly Review'!$C$5) | T17: AI-free first | U17: Revised schedule | V17: 24-Week Plan!D5 Weekly Task Navigator!E5 | X17: 1 | Y17: Weekly problem set | AD17: =IF(G17="Done",IF(H17="","Add evidence",IF(R17="","Add completion date",IF(D17="Mock",IF(OR(Z17="",AA17="",AB17="",AB17="Not Attempted"),"Record mock results","Complete"),"Complete"))),"") | AE17: =C17&"|"&COUNTIFS($C$6:C17,C17) -> DSA|1
A18: RW20 | B18: 1 | C18: Engineering | D18: Practice | E18: Think-aloud communication | F18: P0 | G18: Not started | J18: =IF('Weekly Review'!$C$4="","",'Weekly Review'!$C$4+(X18-1)*7+6) -> 46300 | K18: Core | L18: 1 | M18: 0 | N18: 0 | O18: Clear reasoning without constant chatter Clarify, plan, narrate decisions without rambling | P18: Narrate plan, uncertainty, choices and validation Practice mode: AI-free Yes, AI-assisted Yes | S18: =IF(R18="","",R18+'Weekly Review'!$C$5) | T18: AI-free first | U18: Merged | V18: Real-World Eng!20 Master Roadmap!78 | W18: S021 | X18: 1 | Y18: Think-aloud communication | AC18: W1 + every mock Review: W4 + W21–24 W1 + throughout | AD18: =IF(G18="Done",IF(H18="","Add evidence",IF(R18="","Add completion date",IF(D18="Mock",IF(OR(Z18="",AA18="",AB18="",AB18="Not Attempted"),"Record mock results","Complete"),"Complete"))),"") | AE18: =C18&"|"&COUNTIFS($C$6:C18,C18) -> Engineering|3
A19: M01 | B19: 1 | C19: Mock interviews | D19: Mock | E19: Java Big-O/arrays/OOP + verbal reasoning | F19: P0 | G19: Not started | J19: =IF('Weekly Review'!$C$4="","",'Weekly Review'!$C$4+(X19-1)*7+6) -> 46300 | K19: Core | L19: 1 | M19: 0 | N19: 0 | O19: Complete the timed round. Record technical and communication scores, result, evidence, and one correction before the next mock. | S19: =IF(R19="","",R19+'Weekly Review'!$C$5) | T19: AI-Free | U19: Existing | V19: Mock Interviews!5 | X19: 1 | Y19: Foundations + Coding | AB19: Not Attempted | AD19: =IF(G19="Done",IF(H19="","Add evidence",IF(R19="","Add completion date",IF(D19="Mock",IF(OR(Z19="",AA19="",AB19="",AB19="Not Attempted"),"Record mock results","Complete"),"Complete"))),"") | AE19: =C19&"|"&COUNTIFS($C$6:C19,C19) -> Mock interviews|1
A20: RV01 | B20: 1 | C20: Review | D20: Review | E20: Review evidence, questions and next-week capacity | F20: P1 | G20: Not started | I20: Record weakest concept and the next practice date. | J20: =IF('Weekly Review'!$C$4="","",'Weekly Review'!$C$4+(X20-1)*7+6) -> 46300 | K20: Core | L20: 0.5 | M20: 0 | N20: 0 | O20: Revisit due topics, practice the questions introduced this week, capture mock feedback, and choose the next three priorities. Update Weekly Review outcome and adjustment. | S20: =IF(R20="","",R20+'Weekly Review'!$C$5) | T20: AI-free first | U20: New gap task | X20: 1 | Y20: Weekly review | AD20: =IF(G20="Done",IF(H20="","Add evidence",IF(R20="","Add completion date",IF(D20="Mock",IF(OR(Z20="",AA20="",AB20="",AB20="Not Attempted"),"Record mock results","Complete"),"Complete"))),"") | AE20: =C20&"|"&COUNTIFS($C$6:C20,C20) -> Review|2
A21: CS13 | B21: 2 | C21: CS & SQL | D21: Learn | E21: GROUP BY / HAVING | F21: P0 | G21: Not started | J21: =IF('Weekly Review'!$C$4="","",'Weekly Review'!$C$4+(X21-1)*7+6) -> 46307 | K21: Core | L21: 0.75 | M21: 0 | N21: 0 | O21: Aggregate correctly and filter grouped results | P21: Interview: Top customers over threshold | S21: =IF(R21="","",R21+'Weekly Review'!$C$5) | T21: AI-free first | U21: Existing | V21: CS Fundamentals!13 | W21: S020 | X21: 2 | Y21: SQL | AC21: W2 Review: W4 + W21–24 | AD21: =IF(G21="Done",IF(H21="","Add evidence",IF(R21="","Add completion date",IF(D21="Mock",IF(OR(Z21="",AA21="",AB21="",AB21="Not Attempted"),"Record mock results","Complete"),"Complete"))),"") | AE21: =C21&"|"&COUNTIFS($C$6:C21,C21) -> CS & SQL|2
A22: JA07 | B22: 2 | C22: Java & Spring | D22: Learn | E22: equals/hashCode/immutability | F22: P0 | G22: Not started | J22: =IF('Weekly Review'!$C$4="","",'Weekly Review'!$C$4+(X22-1)*7+6) -> 46307 | K22: Core | L22: 0.75 | M22: 0 | N22: 0 | O22: identity vs equality, hash contracts, immutable value objects | P22: value object kata Interview: why can HashMap fail with bad hashCode? | Q22: G02 | S22: =IF(R22="","",R22+'Weekly Review'!$C$5) | T22: AI-free first | U22: Existing | V22: Java + Spring Boot!7 | W22: S001 | X22: 2 | Y22: Java Core | AC22: W2 Review: W4 + W21–24 | AD22: =IF(G22="Done",IF(H22="","Add evidence",IF(R22="","Add completion date",IF(D22="Mock",IF(OR(Z22="",AA22="",AB22="",AB22="Not Attempted"),"Record mock results","Complete"),"Complete"))),"") | AE22: =C22&"|"&COUNTIFS($C$6:C22,C22) -> Java & Spring|3
A23: JA08 | B23: 2 | C23: Java & Spring | D23: Learn | E23: Collections | F23: P0 | G23: Not started | J23: =IF('Weekly Review'!$C$4="","",'Weekly Review'!$C$4+(X23-1)*7+6) -> 46307 | K23: Core | L23: 0.75 | M23: 0 | N23: 0 | O23: List/Set/Map/Queue, implementations, complexity Choose List/Set/Map/Queue; generics bounds; equality/hashCode | P23: collection selection drills Interview: ArrayList vs LinkedList? HashMap internals high level? Implement domain collections exercises | Q23: G02 | S23: =IF(R23="","",R23+'Weekly Review'!$C$5) | T23: AI-free first | U23: Merged | V23: Java + Spring Boot!8 Master Roadmap!82 | W23: S001 | X23: 2 | Y23: Java Core | AC23: W2 Review: W4 + W21–24 W3 | AD23: =IF(G23="Done",IF(H23="","Add evidence",IF(R23="","Add completion date",IF(D23="Mock",IF(OR(Z23="",AA23="",AB23="",AB23="Not Attempted"),"Record mock results","Complete"),"Complete"))),"") | AE23: =C23&"|"&COUNTIFS($C$6:C23,C23) -> Java & Spring|4
A24: TS06 | B24: 2 | C24: TypeScript & UI | D24: Learn | E24: Objects / prototypes | F24: P1 | G24: Not started | J24: =IF('Weekly Review'!$C$4="","",'Weekly Review'!$C$4+(X24-1)*7+6) -> 46307 | K24: Core | L24: 0.75 | M24: 0 | N24: 0 | O24: object semantics, prototype chain high level, this behavior | P24: object method drills Interview: arrow vs function this? | Q24: G02 | S24: =IF(R24="","",R24+'Weekly Review'!$C$5) | T24: AI-free first | U24: Existing | V24: TypeScript Track!6 | W24: S014 | X24: 2 | Y24: JavaScript Core | AC24: W2 Review: W4 + W21–24 | AD24: =IF(G24="Done",IF(H24="","Add evidence",IF(R24="","Add completion date",IF(D24="Mock",IF(OR(Z24="",AA24="",AB24="",AB24="Not Attempted"),"Record mock results","Complete"),"Complete"))),"") | AE24: =C24&"|"&COUNTIFS($C$6:C24,C24) -> TypeScript & UI|4
A25: TS09 | B25: 2 | C25: TypeScript & UI | D25: Learn | E25: Union/intersection/narrowing | F25: P0 | G25: Not started | J25: =IF('Weekly Review'!$C$4="","",'Weekly Review'!$C$4+(X25-1)*7+6) -> 46307 | K25: Core | L25: 0.75 | M25: 0 | N25: 0 | O25: discriminated unions, guards, exhaustive checks | P25: typed state machine Interview: how model API states safely? | Q25: G02 | S25: =IF(R25="","",R25+'Weekly Review'!$C$5) | T25: AI-free first | U25: Existing | V25: TypeScript Track!9 | W25: S015 | X25: 2 | Y25: TypeScript Core | AC25: W2 Review: W4 + W21–24 | AD25: =IF(G25="Done",IF(H25="","Add evidence",IF(R25="","Add completion date",IF(D25="Mock",IF(OR(Z25="",AA25="",AB25="",AB25="Not Attempted"),"Record mock results","Complete"),"Complete"))),"") | AE25: =C25&"|"&COUNTIFS($C$6:C25,C25) -> TypeScript & UI|5
A26: B02 | B26: 2 | C26: Projects | D26: Build | E26: Immutable Java value objects + typed TS API-state exercise | F26: P1 | G26: Not started | J26: =IF('Weekly Review'!$C$4="","",'Weekly Review'!$C$4+(X26-1)*7+6) -> 46307 | K26: Core | L26: 2 | M26: 0 | N26: 0 | O26: Demonstrate the working output, relevant tests, and one design trade-off. | P26: CS/SQL: SOLID basics + GROUP BY/HAVING Design: REST resources, methods, status codes AI practice: AI-free; compare your solution with AI only after completion Immutable Java value objects + typed TS API-state exercise Refine REST resources, methods and status-code choices No-AI first; compare with AI only after you finish | Q26: B01 | S26: =IF(R26="","",R26+'Weekly Review'!$C$5) | T26: AI-free first | U26: Merged | V26: 24-Week Plan!6 Weekly Task Navigator!6 | X26: 2 | Y26: Dual Foundations | AD26: =IF(G26="Done",IF(H26="","Add evidence",IF(R26="","Add completion date",IF(D26="Mock",IF(OR(Z26="",AA26="",AB26="",AB26="Not Attempted"),"Record mock results","Complete"),"Complete"))),"") | AE26: =C26&"|"&COUNTIFS($C$6:C26,C26) -> Projects|2
A27: DS02 | B27: 2 | C27: DSA | D27: Practice | E27: Solve 7 new DSA problems and revisit errors | F27: P0 | G27: Not started | J27: =IF('Weekly Review'!$C$4="","",'Weekly Review'!$C$4+(X27-1)*7+6) -> 46307 | K27: Core | L27: 3 | M27: 0 | N27: 0 | O27: Record 7 distinct new problem IDs, explain complexity, and retry one earlier mistake without hints. | P27: Strings (bank target 7) Hash map / set (bank target 10) Two pointers (bank target 8) Use Practice Bank for topic totals. Do not count repeat solutions as new problems. | S27: =IF(R27="","",R27+'Weekly Review'!$C$5) | T27: AI-free first | U27: Revised schedule | V27: 24-Week Plan!D6 Weekly Task Navigator!E6 | X27: 2 | Y27: Weekly problem set | AD27: =IF(G27="Done",IF(H27="","Add evidence",IF(R27="","Add completion date",IF(D27="Mock",IF(OR(Z27="",AA27="",AB27="",AB27="Not Attempted"),"Record mock results","Complete"),"Complete"))),"") | AE27: =C27&"|"&COUNTIFS($C$6:C27,C27) -> DSA|2
A28: G03 | B28: 2 | C28: Career | D28: Career | E28: Create a role shortlist and requirements checklist | F28: P1 | G28: Not started | J28: =IF('Weekly Review'!$C$4="","",'Weekly Review'!$C$4+(X28-1)*7+6) -> 46307 | K28: Core | L28: 0.75 | M28: 0 | N28: 0 | O28: Capture five relevant role descriptions, their required skills and permitted assessment tools. Select a primary role focus. | S28: =IF(R28="","",R28+'Weekly Review'!$C$5) | T28: AI-free first | U28: New gap task | X28: 2 | Y28: Gap closure | AD28: =IF(G28="Done",IF(H28="","Add evidence",IF(R28="","Add completion date",IF(D28="Mock",IF(OR(Z28="",AA28="",AB28="",AB28="Not Attempted"),"Record mock results","Complete"),"Complete"))),"") | AE28: =C28&"|"&COUNTIFS($C$6:C28,C28) -> Career|1
A29: M02 | B29: 2 | C29: Mock interviews | D29: Mock | E29: HashMap/two pointers + Java collections | F29: P0 | G29: Not started | J29: =IF('Weekly Review'!$C$4="","",'Weekly Review'!$C$4+(X29-1)*7+6) -> 46307 | K29: Core | L29: 1 | M29: 0 | N29: 0 | O29: Complete the timed round. Record technical and communication scores, result, evidence, and one correction before the next mock. | S29: =IF(R29="","",R29+'Weekly Review'!$C$5) | T29: AI-Free | U29: Existing | V29: Mock Interviews!6 | X29: 2 | Y29: Coding | AB29: Not Attempted | AD29: =IF(G29="Done",IF(H29="","Add evidence",IF(R29="","Add completion date",IF(D29="Mock",IF(OR(Z29="",AA29="",AB29="",AB29="Not Attempted"),"Record mock results","Complete"),"Complete"))),"") | AE29: =C29&"|"&COUNTIFS($C$6:C29,C29) -> Mock interviews|2
A30: RV02 | B30: 2 | C30: Review | D30: Review | E30: Review evidence, questions and next-week capacity | F30: P1 | G30: Not started | I30: Record weakest concept and the next practice date. | J30: =IF('Weekly Review'!$C$4="","",'Weekly Review'!$C$4+(X30-1)*7+6) -> 46307 | K30: Core | L30: 0.5 | M30: 0 | N30: 0 | O30: Revisit due topics, practice the questions introduced this week, capture mock feedback, and choose the next three priorities. Update Weekly Review outcome and adjustment. | S30: =IF(R30="","",R30+'Weekly Review'!$C$5) | T30: AI-free first | U30: New gap task | X30: 2 | Y30: Weekly review | AD30: =IF(G30="Done",IF(H30="","Add evidence",IF(R30="","Add completion date",IF(D30="Mock",IF(OR(Z30="",AA30="",AB30="",AB30="Not Attempted"),"Record mock results","Complete"),"Complete"))),"") | AE30: =C30&"|"&COUNTIFS($C$6:C30,C30) -> Review|3
A31: CS07 | B31: 3 | C31: CS & SQL | D31: Learn | E31: ACID | F31: P0 | G31: Not started | J31: =IF('Weekly Review'!$C$4="","",'Weekly Review'!$C$4+(X31-1)*7+6) -> 46314 | K31: Core | L31: 0.75 | M31: 0 | N31: 0 | O31: Explain each property using payment/order example | P31: Interview: Why do transactions matter? | S31: =IF(R31="","",R31+'Weekly Review'!$C$5) | T31: AI-free first | U31: Existing | V31: CS Fundamentals!7 | W31: S019 | X31: 3 | Y31: DBMS | AC31: W3 Review: W4 + W21–24 | AD31: =IF(G31="Done",IF(H31="","Add evidence",IF(R31="","Add completion date",IF(D31="Mock",IF(OR(Z31="",AA31="",AB31="",AB31="Not Attempted"),"Record mock results","Complete"),"Complete"))),"") | AE31: =C31&"|"&COUNTIFS($C$6:C31,C31) -> CS & SQL|3
A32: CS08 | B32: 3 | C32: CS & SQL | D32: Learn | E32: Normalization | F32: P1 | G32: Not started | J32: =IF('Weekly Review'!$C$4="","",'Weekly Review'!$C$4+(X32-1)*7+6) -> 46314 | K32: Core | L32: 0.75 | M32: 0 | N32: 0 | O32: 1NF/2NF/3NF and denormalization trade-offs DDL/DML, joins, constraints, indexes, transactions, isolation Schema, constraints, transactions, indexes, EXPLAIN basics 1NF–3NF reasoning, entities, cardinality, integrity | P32: Interview: Normalize this schema Design + query a commerce schema Schema + 20 SQL questions Shared database foundation | S32: =IF(R32="","",R32+'Weekly Review'!$C$5) | T32: AI-free first | U32: Merged | V32: CS Fundamentals!8 Full-Stack Stack!15 Master Roadmap!26 Master Roadmap!27 | W32: S019 S004 S020 | X32: 3 | Y32: DBMS | AC32: W3 Review: W4 + W21–24 W3–10 | AD32: =IF(G32="Done",IF(H32="","Add evidence",IF(R32="","Add completion date",IF(D32="Mock",IF(OR(Z32="",AA32="",AB32="",AB32="Not Attempted"),"Record mock results","Complete"),"Complete"))),"") | AE32: =C32&"|"&COUNTIFS($C$6:C32,C32) -> CS & SQL|4
A33: JA09 | B33: 3 | C33: Java & Spring | D33: Learn | E33: Generics | F33: P1 | G33: Not started | J33: =IF('Weekly Review'!$C$4="","",'Weekly Review'!$C$4+(X33-1)*7+6) -> 46314 | K33: Core | L33: 0.75 | M33: 0 | N33: 0 | O33: type parameters, bounds, invariance, wildcards basics | P33: generic repository/filter exercise Interview: ? extends vs ? super? | Q33: G02 | S33: =IF(R33="","",R33+'Weekly Review'!$C$5) | T33: AI-free first | U33: Existing | V33: Java + Spring Boot!9 | W33: S001 | X33: 3 | Y33: Java Core | AC33: W3 Review: W4 + W21–24 | AD33: =IF(G33="Done",IF(H33="","Add evidence",IF(R33="","Add completion date",IF(D33="Mock",IF(OR(Z33="",AA33="",AB33="",AB33="Not Attempted"),"Record mock results","Complete"),"Complete"))),"") | AE33: =C33&"|"&COUNTIFS($C$6:C33,C33) -> Java & Spring|5
A34: JA10 | B34: 3 | C34: Java & Spring | D34: Learn | E34: Exceptions | F34: P0 | G34: Not started | J34: =IF('Weekly Review'!$C$4="","",'Weekly Review'!$C$4+(X34-1)*7+6) -> 46314 | K34: Core | L34: 0.75 | M34: 0 | N34: 0 | O34: checked/unchecked, custom exceptions, try-with-resources Design error boundaries, retries, typed errors, failure paths | P34: API exception taxonomy Interview: when should you catch vs propagate? | Q34: G02 | S34: =IF(R34="","",R34+'Weekly Review'!$C$5) | T34: AI-free first | U34: Merged | V34: Java + Spring Boot!10 Master Roadmap!23 | W34: S001 S026 | X34: 3 | Y34: Java Core | AC34: W3 Review: W4 + W21–24 | AD34: =IF(G34="Done",IF(H34="","Add evidence",IF(R34="","Add completion date",IF(D34="Mock",IF(OR(Z34="",AA34="",AB34="",AB34="Not Attempted"),"Record mock results","Complete"),"Complete"))),"") | AE34: =C34&"|"&COUNTIFS($C$6:C34,C34) -> Java & Spring|6
A35: TS10 | B35: 3 | C35: TypeScript & UI | D35: Learn | E35: Generics | F35: P0 | G35: Not started | J35: =IF('Weekly Review'!$C$4="","",'Weekly Review'!$C$4+(X35-1)*7+6) -> 46314 | K35: Core | L35: 0.75 | M35: 0 | N35: 0 | O35: generic functions/types, constraints, inference | P35: generic table/API helper Interview: generic vs union? | Q35: G02 | S35: =IF(R35="","",R35+'Weekly Review'!$C$5) | T35: AI-free first | U35: Existing | V35: TypeScript Track!10 | W35: S016 | X35: 3 | Y35: TypeScript Core | AC35: W3 Review: W4 + W21–24 | AD35: =IF(G35="Done",IF(H35="","Add evidence",IF(R35="","Add completion date",IF(D35="Mock",IF(OR(Z35="",AA35="",AB35="",AB35="Not Attempted"),"Record mock results","Complete"),"Complete"))),"") | AE35: =C35&"|"&COUNTIFS($C$6:C35,C35) -> TypeScript & UI|6
A36: TS11 | B36: 3 | C36: TypeScript & UI | D36: Learn | E36: Utility / mapped types | F36: P1 | G36: Not started | J36: =IF('Weekly Review'!$C$4="","",'Weekly Review'!$C$4+(X36-1)*7+6) -> 46314 | K36: Core | L36: 0.75 | M36: 0 | N36: 0 | O36: Partial, Pick, Omit, Record; mapped/conditional concepts | P36: DTO transformation examples Interview: when are utility types useful/dangerous? | Q36: G02 | S36: =IF(R36="","",R36+'Weekly Review'!$C$5) | T36: AI-free first | U36: Existing | V36: TypeScript Track!11 | W36: S015 | X36: 3 | Y36: TypeScript Core | AC36: W3 Review: W4 + W21–24 | AD36: =IF(G36="Done",IF(H36="","Add evidence",IF(R36="","Add completion date",IF(D36="Mock",IF(OR(Z36="",AA36="",AB36="",AB36="Not Attempted"),"Record mock results","Complete"),"Complete"))),"") | AE36: =C36&"|"&COUNTIFS($C$6:C36,C36) -> TypeScript & UI|7
A37: TS12 | B37: 3 | C37: TypeScript & UI | D37: Learn | E37: Interfaces vs type aliases | F37: P1 | G37: Not started | J37: =IF('Weekly Review'!$C$4="","",'Weekly Review'!$C$4+(X37-1)*7+6) -> 46314 | K37: Core | L37: 0.75 | M37: 0 | N37: 0 | O37: extension, unions, declaration merging concept | P37: model API contracts both ways Interview: interface vs type? | Q37: G02 | S37: =IF(R37="","",R37+'Weekly Review'!$C$5) | T37: AI-free first | U37: Existing | V37: TypeScript Track!12 | W37: S016 | X37: 3 | Y37: TypeScript Core | AC37: W3 Review: W4 + W21–24 | AD37: =IF(G37="Done",IF(H37="","Add evidence",IF(R37="","Add completion date",IF(D37="Mock",IF(OR(Z37="",AA37="",AB37="",AB37="Not Attempted"),"Record mock results","Complete"),"Complete"))),"") | AE37: =C37&"|"&COUNTIFS($C$6:C37,C37) -> TypeScript & UI|8
A38: B03 | B38: 3 | C38: Projects | D38: Build | E38: Generic Java service + typed DTO transformations | F38: P1 | G38: Not started | J38: =IF('Weekly Review'!$C$4="","",'Weekly Review'!$C$4+(X38-1)*7+6) -> 46314 | K38: Core | L38: 2 | M38: 0 | N38: 0 | O38: Demonstrate the working output, relevant tests, and one design trade-off. | P38: CS/SQL: ACID + normalization + SQL aggregates Design: Schema, keys, constraints and relationships AI practice: AI-free first; use AI only for critique Generic Java service + typed DTO transformations Add keys, relationships, uniqueness and validation constraints Use AI only as a critic; keep implementation independent | Q38: B02 | S38: =IF(R38="","",R38+'Weekly Review'!$C$5) | T38: AI-free first | U38: Merged | V38: 24-Week Plan!7 Weekly Task Navigator!7 | X38: 3 | Y38: Dual Foundations | AD38: =IF(G38="Done",IF(H38="","Add evidence",IF(R38="","Add completion date",IF(D38="Mock",IF(OR(Z38="",AA38="",AB38="",AB38="Not Attempted"),"Record mock results","Complete"),"Complete"))),"") | AE38: =C38&"|"&COUNTIFS($C$6:C38,C38) -> Projects|3
A39: DS03 | B39: 3 | C39: DSA | D39: Practice | E39: Solve 7 new DSA problems and revisit errors | F39: P0 | G39: Not started | J39: =IF('Weekly Review'!$C$4="","",'Weekly Review'!$C$4+(X39-1)*7+6) -> 46314 | K39: Core | L39: 3 | M39: 0 | N39: 0 | O39: Record 7 distinct new problem IDs, explain complexity, and retry one earlier mistake without hints. | P39: Sliding window (bank target 9) Prefix sum (bank target 6) Use Practice Bank for topic totals. Do not count repeat solutions as new problems. | S39: =IF(R39="","",R39+'Weekly Review'!$C$5) | T39: AI-free first | U39: Revised schedule | V39: 24-Week Plan!D7 Weekly Task Navigator!E7 | X39: 3 | Y39: Weekly problem set | AD39: =IF(G39="Done",IF(H39="","Add evidence",IF(R39="","Add completion date",IF(D39="Mock",IF(OR(Z39="",AA39="",AB39="",AB39="Not Attempted"),"Record mock results","Complete"),"Complete"))),"") | AE39: =C39&"|"&COUNTIFS($C$6:C39,C39) -> DSA|3
A40: M03 | B40: 3 | C40: Mock interviews | D40: Mock | E40: Sliding window/prefix + generics + SQL | F40: P0 | G40: Not started | J40: =IF('Weekly Review'!$C$4="","",'Weekly Review'!$C$4+(X40-1)*7+6) -> 46314 | K40: Core | L40: 1 | M40: 0 | N40: 0 | O40: Complete the timed round. Record technical and communication scores, result, evidence, and one correction before the next mock. | S40: =IF(R40="","",R40+'Weekly Review'!$C$5) | T40: AI-Free | U40: Existing | V40: Mock Interviews!7 | X40: 3 | Y40: Coding + SQL | AB40: Not Attempted | AD40: =IF(G40="Done",IF(H40="","Add evidence",IF(R40="","Add completion date",IF(D40="Mock",IF(OR(Z40="",AA40="",AB40="",AB40="Not Attempted"),"Record mock results","Complete"),"Complete"))),"") | AE40: =C40&"|"&COUNTIFS($C$6:C40,C40) -> Mock interviews|3
A41: RV03 | B41: 3 | C41: Review | D41: Review | E41: Review evidence, questions and next-week capacity | F41: P1 | G41: Not started | I41: Record weakest concept and the next practice date. | J41: =IF('Weekly Review'!$C$4="","",'Weekly Review'!$C$4+(X41-1)*7+6) -> 46314 | K41: Core | L41: 0.5 | M41: 0 | N41: 0 | O41: Revisit due topics, practice the questions introduced this week, capture mock feedback, and choose the next three priorities. Update Weekly Review outcome and adjustment. | S41: =IF(R41="","",R41+'Weekly Review'!$C$5) | T41: AI-free first | U41: New gap task | X41: 3 | Y41: Weekly review | AD41: =IF(G41="Done",IF(H41="","Add evidence",IF(R41="","Add completion date",IF(D41="Mock",IF(OR(Z41="",AA41="",AB41="",AB41="Not Attempted"),"Record mock results","Complete"),"Complete"))),"") | AE41: =C41&"|"&COUNTIFS($C$6:C41,C41) -> Review|4
...

Sheet AI Engineering
A2: AI Engineering tasks
A4: Category | C4: AI Engineering | D4: Tasks | E4: =COUNTIFS(PlanTasks[Category],$C$4) -> 7 | F4: Complete | G4: =COUNTIFS(PlanTasks[Category],$C$4,PlanTasks[Completion check],"Complete") -> 0 | H4: Progress | I4: =IF(E4=0,"",G4/E4) -> 0
A5: Linked view. Edit the Master Plan; changes appear here automatically. Use Task ID to find the original row.
A6: =IF(E4>300,"More than 300 tasks: copy the last view row downward to show the remaining tasks.","Shows up to 300 tasks. Order follows the Master Plan.") -> Shows up to 300 tasks. Order follows the Master Plan.
A8: Task ID | B8: Start week | C8: Task / deliverable | D8: Status | E8: Priority | F8: Scope | G8: Estimate (h) | H8: Actual (h) | I8: Due date | J8: Completion check | K8: Next action / blocker | L8: Done when | M8: Exercise / interview prompt | N8: Prerequisite IDs | O8: Plan section | P8: Category | Q8: Evidence / result | R8: Completed on | S8: Review due | T8: AI practice mode | U8: Source IDs | V8: Source position
A9: {=IF($V9="","",INDEX(PlanTasks[Task ID],$V9))} -> AI18 | B9: {=IF($V9="","",IF(INDEX(PlanTasks[Start week],$V9)="","",INDEX(PlanTasks[Start week],$V9)))} -> 1 | C9: {=IF($V9="","",IF(INDEX(PlanTasks[Task / deliverable],$V9)="","",INDEX(PlanTasks[Task / deliverable],$V9)))} -> Confirm round policy and rehearse AI-free fallback | D9: {=IF($V9="","",IF(INDEX(PlanTasks[Status],$V9)="","",INDEX(PlanTasks[Status],$V9)))} -> In progress | E9: {=IF($V9="","",IF(INDEX(PlanTasks[Priority],$V9)="","",INDEX(PlanTasks[Priority],$V9)))} -> P0 | F9: {=IF($V9="","",IF(INDEX(PlanTasks[Scope],$V9)="","",INDEX(PlanTasks[Scope],$V9)))} -> Core | G9: {=IF($V9="","",IF(INDEX(PlanTasks[Estimate (h)],$V9)="","",INDEX(PlanTasks[Estimate (h)],$V9)))} -> 0.75 | H9: {=IF($V9="","",IF(INDEX(PlanTasks[Actual (h)],$V9)="","",INDEX(PlanTasks[Actual (h)],$V9)))} -> 0 | I9: {=IF($V9="","",IF(INDEX(PlanTasks[Due date],$V9)="","",INDEX(PlanTasks[Due date],$V9)))} -> 46300 | J9: {=IF($V9="","",IF(INDEX(PlanTasks[Completion check],$V9)="","",INDEX(PlanTasks[Completion check],$V9)))} | K9: {=IF($V9="","",IF(INDEX(PlanTasks[Next action / blocker],$V9)="","",INDEX(PlanTasks[Next action / blocker],$V9)))} | L9: {=IF($V9="","",IF(INDEX(PlanTasks[Done when],$V9)="","",INDEX(PlanTasks[Done when],$V9)))} -> Confirm exact permitted tools and boundaries Code/debug/explain with no assistant Implement and explain independently Solve/debug/explain without AI when required | M9: {=IF($V9="","",IF(INDEX(PlanTasks[Exercise / interview prompt],$V9)="","",INDEX(PlanTasks[Exercise / interview prompt],$V9)))} -> Transparent AI-assisted session Failure to test: Policy violation 60-min unaided mock Failure to test: Dependency on tools Redo representative task without any assistant Practice mode: AI-free Yes, AI-assisted No | N9: {=IF($V9="","",IF(INDEX(PlanTasks[Prerequisite IDs],$V9)="","",INDEX(PlanTasks[Prerequisite IDs],$V9)))} | O9: {=IF($V9="","",IF(INDEX(PlanTasks[Plan section],$V9)="","",INDEX(PlanTasks[Plan section],$V9)))} -> Interview Policy | P9: {=IF($V9="","",IF(INDEX(PlanTasks[Category],$V9)="","",INDEX(PlanTasks[Category],$V9)))} -> AI Engineering | Q9: {=IF($V9="","",IF(INDEX(PlanTasks[Evidence / result],$V9)="","",INDEX(PlanTasks[Evidence / result],$V9)))} | R9: {=IF($V9="","",IF(INDEX(PlanTasks[Completed on],$V9)="","",INDEX(PlanTasks[Completed on],$V9)))} | S9: {=IF($V9="","",IF(INDEX(PlanTasks[Review due],$V9)="","",INDEX(PlanTasks[Review due],$V9)))} | T9: {=IF($V9="","",IF(INDEX(PlanTasks[AI practice mode],$V9)="","",INDEX(PlanTasks[AI practice mode],$V9)))} -> AI-free first | U9: {=IF($V9="","",IF(INDEX(PlanTasks[Source IDs],$V9)="","",INDEX(PlanTasks[Source IDs],$V9)))} -> S026 S027 S025 | V9: =IF(ROW()-8>$E$4,"",MATCH($C$4&"|"&(ROW()-8),PlanTasks[Category key],0)) -> 3
A10: {=IF($V10="","",INDEX(PlanTasks[Task ID],$V10))} -> AI05 | B10: {=IF($V10="","",IF(INDEX(PlanTasks[Start week],$V10)="","",INDEX(PlanTasks[Start week],$V10)))} -> 5 | C10: {=IF($V10="","",IF(INDEX(PlanTasks[Task / deliverable],$V10)="","",INDEX(PlanTasks[Task / deliverable],$V10)))} -> AI limitations, context and token budgets | D10: {=IF($V10="","",IF(INDEX(PlanTasks[Status],$V10)="","",INDEX(PlanTasks[Status],$V10)))} -> Not started | E10: {=IF($V10="","",IF(INDEX(PlanTasks[Priority],$V10)="","",INDEX(PlanTasks[Priority],$V10)))} -> P1 | F10: {=IF($V10="","",IF(INDEX(PlanTasks[Scope],$V10)="","",INDEX(PlanTasks[Scope],$V10)))} -> Core | G10: {=IF($V10="","",IF(INDEX(PlanTasks[Estimate (h)],$V10)="","",INDEX(PlanTasks[Estimate (h)],$V10)))} -> 0.75 | H10: {=IF($V10="","",IF(INDEX(PlanTasks[Actual (h)],$V10)="","",INDEX(PlanTasks[Actual (h)],$V10)))} -> 0 | I10: {=IF($V10="","",IF(INDEX(PlanTasks[Due date],$V10)="","",INDEX(PlanTasks[Due date],$V10)))} -> 46328 | J10: {=IF($V10="","",IF(INDEX(PlanTasks[Completion check],$V10)="","",INDEX(PlanTasks[Completion check],$V10)))} | K10: {=IF($V10="","",IF(INDEX(PlanTasks[Next action / blocker],$V10)="","",INDEX(PlanTasks[Next action / blocker],$V10)))} | L10: {=IF($V10="","",IF(INDEX(PlanTasks[Done when],$V10)="","",INDEX(PlanTasks[Done when],$V10)))} -> Context limits, cost/latency, truncation Hallucination, stale assumptions, non-determinism Models, tokens, context, latency/cost, failure handling | M10: {=IF($V10="","",IF(INDEX(PlanTasks[Exercise / interview prompt],$V10)="","",INDEX(PlanTasks[Exercise / interview prompt],$V10)))} -> Estimate context needed for repo task Failure to test: Missing/irrelevant context Find unsupported claim/code assumption Failure to test: Blind trust | N10: {=IF($V10="","",IF(INDEX(PlanTasks[Prerequisite IDs],$V10)="","",INDEX(PlanTasks[Prerequisite IDs],$V10)))} | O10: {=IF($V10="","",IF(INDEX(PlanTasks[Plan section],$V10)="","",INDEX(PlanTasks[Plan section],$V10)))} -> Fundamentals | P10: {=IF($V10="","",IF(INDEX(PlanTasks[Category],$V10)="","",INDEX(PlanTasks[Category],$V10)))} -> AI Engineering | Q10: {=IF($V10="","",IF(INDEX(PlanTasks[Evidence / result],$V10)="","",INDEX(PlanTasks[Evidence / result],$V10)))} | R10: {=IF($V10="","",IF(INDEX(PlanTasks[Completed on],$V10)="","",INDEX(PlanTasks[Completed on],$V10)))} | S10: {=IF($V10="","",IF(INDEX(PlanTasks[Review due],$V10)="","",INDEX(PlanTasks[Review due],$V10)))} | T10: {=IF($V10="","",IF(INDEX(PlanTasks[AI practice mode],$V10)="","",INDEX(PlanTasks[AI practice mode],$V10)))} -> AI-free first | U10: {=IF($V10="","",IF(INDEX(PlanTasks[Source IDs],$V10)="","",INDEX(PlanTasks[Source IDs],$V10)))} -> S004 S023 | V10: =IF(ROW()-8>$E$4,"",MATCH($C$4&"|"&(ROW()-8),PlanTasks[Category key],0)) -> 50
A11: {=IF($V11="","",INDEX(PlanTasks[Task ID],$V11))} -> AI07 | B11: {=IF($V11="","",IF(INDEX(PlanTasks[Start week],$V11)="","",INDEX(PlanTasks[Start week],$V11)))} -> 8 | C11: {=IF($V11="","",IF(INDEX(PlanTasks[Task / deliverable],$V11)="","",INDEX(PlanTasks[Task / deliverable],$V11)))} -> LLM integration and validated structured output | D11: {=IF($V11="","",IF(INDEX(PlanTasks[Status],$V11)="","",INDEX(PlanTasks[Status],$V11)))} -> Not started | E11: {=IF($V11="","",IF(INDEX(PlanTasks[Priority],$V11)="","",INDEX(PlanTasks[Priority],$V11)))} -> P1 | F11: {=IF($V11="","",IF(INDEX(PlanTasks[Scope],$V11)="","",INDEX(PlanTasks[Scope],$V11)))} -> Optional | G11: {=IF($V11="","",IF(INDEX(PlanTasks[Estimate (h)],$V11)="","",INDEX(PlanTasks[Estimate (h)],$V11)))} -> 0.75 | H11: {=IF($V11="","",IF(INDEX(PlanTasks[Actual (h)],$V11)="","",INDEX(PlanTasks[Actual (h)],$V11)))} -> 0 | I11: {=IF($V11="","",IF(INDEX(PlanTasks[Due date],$V11)="","",INDEX(PlanTasks[Due date],$V11)))} -> 46349 | J11: {=IF($V11="","",IF(INDEX(PlanTasks[Completion check],$V11)="","",INDEX(PlanTasks[Completion check],$V11)))} | K11: {=IF($V11="","",IF(INDEX(PlanTasks[Next action / blocker],$V11)="","",INDEX(PlanTasks[Next action / blocker],$V11)))} | L11: {=IF($V11="","",IF(INDEX(PlanTasks[Done when],$V11)="","",INDEX(PlanTasks[Done when],$V11)))} -> Requests, streaming, timeouts, retries, cost JSON schema / validation / retries Schemas/JSON validation, retries, deterministic handling | M11: {=IF($V11="","",IF(INDEX(PlanTasks[Exercise / interview prompt],$V11)="","",INDEX(PlanTasks[Exercise / interview prompt],$V11)))} -> Build a safe server-side call Failure to test: Secret leakage, retry storms Generate typed object and reject invalid Failure to test: Malformed output | N11: {=IF($V11="","",IF(INDEX(PlanTasks[Prerequisite IDs],$V11)="","",INDEX(PlanTasks[Prerequisite IDs],$V11)))} | O11: {=IF($V11="","",IF(INDEX(PlanTasks[Plan section],$V11)="","",INDEX(PlanTasks[Plan section],$V11)))} -> Integration | P11: {=IF($V11="","",IF(INDEX(PlanTasks[Category],$V11)="","",INDEX(PlanTasks[Category],$V11)))} -> AI Engineering | Q11: {=IF($V11="","",IF(INDEX(PlanTasks[Evidence / result],$V11)="","",INDEX(PlanTasks[Evidence / result],$V11)))} | R11: {=IF($V11="","",IF(INDEX(PlanTasks[Completed on],$V11)="","",INDEX(PlanTasks[Completed on],$V11)))} | S11: {=IF($V11="","",IF(INDEX(PlanTasks[Review due],$V11)="","",INDEX(PlanTasks[Review due],$V11)))} | T11: {=IF($V11="","",IF(INDEX(PlanTasks[AI practice mode],$V11)="","",INDEX(PlanTasks[AI practice mode],$V11)))} -> AI-free first | U11: {=IF($V11="","",IF(INDEX(PlanTasks[Source IDs],$V11)="","",INDEX(PlanTasks[Source IDs],$V11)))} -> S004 S024 | V11: =IF(ROW()-8>$E$4,"",MATCH($C$4&"|"&(ROW()-8),PlanTasks[Category key],0)) -> 85
A12: {=IF($V12="","",INDEX(PlanTasks[Task ID],$V12))} -> AI17 | B12: {=IF($V12="","",IF(INDEX(PlanTasks[Start week],$V12)="","",INDEX(PlanTasks[Start week],$V12)))} -> 11 | C12: {=IF($V12="","",IF(INDEX(PlanTasks[Task / deliverable],$V12)="","",INDEX(PlanTasks[Task / deliverable],$V12)))} -> Secrets/privacy | D12: {=IF($V12="","",IF(INDEX(PlanTasks[Status],$V12)="","",INDEX(PlanTasks[Status],$V12)))} -> Not started | E12: {=IF($V12="","",IF(INDEX(PlanTasks[Priority],$V12)="","",INDEX(PlanTasks[Priority],$V12)))} -> P1 | F12: {=IF($V12="","",IF(INDEX(PlanTasks[Scope],$V12)="","",INDEX(PlanTasks[Scope],$V12)))} -> Core | G12: {=IF($V12="","",IF(INDEX(PlanTasks[Estimate (h)],$V12)="","",INDEX(PlanTasks[Estimate (h)],$V12)))} -> 0.75 | H12: {=IF($V12="","",IF(INDEX(PlanTasks[Actual (h)],$V12)="","",INDEX(PlanTasks[Actual (h)],$V12)))} -> 0 | I12: {=IF($V12="","",IF(INDEX(PlanTasks[Due date],$V12)="","",INDEX(PlanTasks[Due date],$V12)))} -> 46370 | J12: {=IF($V12="","",IF(INDEX(PlanTasks[Completion check],$V12)="","",INDEX(PlanTasks[Completion check],$V12)))} | K12: {=IF($V12="","",IF(INDEX(PlanTasks[Next action / blocker],$V12)="","",INDEX(PlanTasks[Next action / blocker],$V12)))} | L12: {=IF($V12="","",IF(INDEX(PlanTasks[Done when],$V12)="","",INDEX(PlanTasks[Done when],$V12)))} -> Do not expose sensitive secrets/data without authorization Env vars, secret managers, rotation, least privilege | M12: {=IF($V12="","",IF(INDEX(PlanTasks[Exercise / interview prompt],$V12)="","",INDEX(PlanTasks[Exercise / interview prompt],$V12)))} -> Identify sensitive context boundaries Failure to test: Data leakage | N12: {=IF($V12="","",IF(INDEX(PlanTasks[Prerequisite IDs],$V12)="","",INDEX(PlanTasks[Prerequisite IDs],$V12)))} | O12: {=IF($V12="","",IF(INDEX(PlanTasks[Plan section],$V12)="","",INDEX(PlanTasks[Plan section],$V12)))} -> Safety | P12: {=IF($V12="","",IF(INDEX(PlanTasks[Category],$V12)="","",INDEX(PlanTasks[Category],$V12)))} -> AI Engineering | Q12: {=IF($V12="","",IF(INDEX(PlanTasks[Evidence / result],$V12)="","",INDEX(PlanTasks[Evidence / result],$V12)))} | R12: {=IF($V12="","",IF(INDEX(PlanTasks[Completed on],$V12)="","",INDEX(PlanTasks[Completed on],$V12)))} | S12: {=IF($V12="","",IF(INDEX(PlanTasks[Review due],$V12)="","",INDEX(PlanTasks[Review due],$V12)))} | T12: {=IF($V12="","",IF(INDEX(PlanTasks[AI practice mode],$V12)="","",INDEX(PlanTasks[AI practice mode],$V12)))} -> AI-free first | U12: {=IF($V12="","",IF(INDEX(PlanTasks[Source IDs],$V12)="","",INDEX(PlanTasks[Source IDs],$V12)))} -> S025 S022 | V12: =IF(ROW()-8>$E$4,"",MATCH($C$4&"|"&(ROW()-8),PlanTasks[Category key],0)) -> 113
